---------------------------------
[2023-09-10 07:33:45][INFO][200]:La conexion [dbconn_standard] esta desabilitada en el archivo .config
---------------------------------
[2023-09-10 07:33:45][INFO][200]:Iniciando ...
---------------------------------
[2023-09-10 07:33:45][INFO][200]:Se van a inferir 5 entidades
---------------------------------
[2023-09-10 07:34:01][EXCEPTION][500]:PYTHON-EXCEPTION:

>>>>>>>>>>>>>>>[TRACEBACK]<<<<<<<<<<<<<<<

  File "/home/alanromero/crowd-counting/src/inference/main.py", line 10, in <module>
    ProjectDirector.go( sys.argv )
  File "/home/alanromero/crowd-counting/src/inference/System/Director/ProjectDirector.py", line 138, in go
    ProjectDirector().setFlux( argv )
  File "/home/alanromero/crowd-counting/src/inference/System/Director/ProjectDirector.py", line 118, in setFlux
    asyncio.run(self.__play(
  File "/home/alanromero/anaconda3/lib/python3.10/asyncio/runners.py", line 44, in run
    return loop.run_until_complete(main)
  File "/home/alanromero/anaconda3/lib/python3.10/asyncio/base_events.py", line 649, in run_until_complete
    return future.result()
  File "/home/alanromero/crowd-counting/src/inference/System/Director/ProjectDirector.py", line 81, in __play
    person_entities = await infer.create_person_entities(camera_entities)
  File "/home/alanromero/crowd-counting/src/inference/System/App/InferProcedures/InferProcedures.py", line 59, in create_person_entities
    entities.append( await self.orion.infer(camera, filevideo))
  File "/home/alanromero/crowd-counting/src/inference/System/App/OrionProcedures/OrionProcedures.py", line 105, in infer
    entities = self.track_video(filevideo, model, time)
  File "/home/alanromero/crowd-counting/src/inference/System/App/OrionProcedures/OrionProcedures.py", line 132, in track_video
    results = model.track(source=frame, persist=True, classes=0)
  File "/home/alanromero/anaconda3/lib/python3.10/site-packages/ultralytics/engine/model.py", line 254, in track
    from ultralytics.trackers import register_tracker
  File "/home/alanromero/anaconda3/lib/python3.10/site-packages/ultralytics/trackers/__init__.py", line 3, in <module>
    from .bot_sort import BOTSORT
  File "/home/alanromero/anaconda3/lib/python3.10/site-packages/ultralytics/trackers/bot_sort.py", line 8, in <module>
    from .byte_tracker import BYTETracker, STrack
  File "/home/alanromero/anaconda3/lib/python3.10/site-packages/ultralytics/trackers/byte_tracker.py", line 6, in <module>
    from .utils import matching
  File "/home/alanromero/anaconda3/lib/python3.10/site-packages/ultralytics/trackers/utils/matching.py", line 17, in <module>
    import lap

>>>>>>>>>>>>>>[ERROR_DESC]<<<<<<<<<<<<<<<

  [ModuleNotFoundError]:No module named 'lap'

>>>>>>>>>>>>>>>>>>>><<<<<<<<<<<<<<<<<<<<<

