---------------------------------
[2023-09-08 14:57:10][INFO][200]:La conexion [dbconn_standard] esta desabilitada en el archivo .config
---------------------------------
[2023-09-08 14:57:10][INFO][200]:Iniciando ...
---------------------------------
[2023-09-08 14:57:11][INFO][200]:Se van a inferir 3 entidades
---------------------------------
[2023-09-08 14:57:11][EXCEPTION][500]:PYTHON-EXCEPTION:

>>>>>>>>>>>>>>>[TRACEBACK]<<<<<<<<<<<<<<<

  File "/Users/l03542515/Documents/crowd-counting/src/inference/main.py", line 10, in <module>
    ProjectDirector.go( sys.argv )
  File "/Users/l03542515/Documents/crowd-counting/src/inference/System/Director/ProjectDirector.py", line 138, in go
    ProjectDirector().setFlux( argv )
  File "/Users/l03542515/Documents/crowd-counting/src/inference/System/Director/ProjectDirector.py", line 118, in setFlux
    asyncio.run(self.__play(
  File "/opt/anaconda3/lib/python3.9/asyncio/runners.py", line 44, in run
    return loop.run_until_complete(main)
  File "/opt/anaconda3/lib/python3.9/asyncio/base_events.py", line 647, in run_until_complete
    return future.result()
  File "/Users/l03542515/Documents/crowd-counting/src/inference/System/Director/ProjectDirector.py", line 80, in __play
    infer = InferProcedures()
  File "/Users/l03542515/Documents/crowd-counting/src/inference/System/App/InferProcedures/InferProcedures.py", line 37, in __init__
    self.s3_client = boto3.client('s3',
  File "/opt/anaconda3/lib/python3.9/site-packages/boto3/__init__.py", line 92, in client
    return _get_default_session().client(*args, **kwargs)
  File "/opt/anaconda3/lib/python3.9/site-packages/boto3/session.py", line 299, in client
    return self._session.create_client(
  File "/opt/anaconda3/lib/python3.9/site-packages/botocore/session.py", line 950, in create_client
    client = client_creator.create_client(
  File "/opt/anaconda3/lib/python3.9/site-packages/botocore/client.py", line 111, in create_client
    service_model = self._load_service_model(service_name, api_version)
  File "/opt/anaconda3/lib/python3.9/site-packages/botocore/client.py", line 202, in _load_service_model
    json_model = self._loader.load_service_model(
  File "/opt/anaconda3/lib/python3.9/site-packages/botocore/loaders.py", line 142, in _wrapper
    data = func(self, *args, **kwargs)
  File "/opt/anaconda3/lib/python3.9/site-packages/botocore/loaders.py", line 417, in load_service_model
    model = self.load_data(full_path)
  File "/opt/anaconda3/lib/python3.9/site-packages/botocore/loaders.py", line 142, in _wrapper
    data = func(self, *args, **kwargs)
  File "/opt/anaconda3/lib/python3.9/site-packages/botocore/loaders.py", line 458, in load_data
    raise DataNotFoundError(data_path=name)

>>>>>>>>>>>>>>[ERROR_DESC]<<<<<<<<<<<<<<<

  [DataNotFoundError]:Unable to load data for: s3/XIKg1pjICy6BS9x6Iua7kFdyTbZUzS2Ow6FKuqW0/service-2

>>>>>>>>>>>>>>>>>>>><<<<<<<<<<<<<<<<<<<<<

