---------------------------------
[2023-09-08 15:01:15][INFO][200]:La conexion [dbconn_standard] esta desabilitada en el archivo .config
---------------------------------
[2023-09-08 15:01:15][INFO][200]:Iniciando ...
---------------------------------
[2023-09-08 15:01:15][INFO][200]:Se van a inferir 3 entidades
---------------------------------
[2023-09-08 15:01:16][EXCEPTION][500]:PYTHON-EXCEPTION:

>>>>>>>>>>>>>>>[TRACEBACK]<<<<<<<<<<<<<<<

  File "/Users/l03542515/Documents/crowd-counting/src/inference/main.py", line 10, in <module>
    ProjectDirector.go( sys.argv )
  File "/Users/l03542515/Documents/crowd-counting/src/inference/System/Director/ProjectDirector.py", line 138, in go
    ProjectDirector().setFlux( argv )
  File "/Users/l03542515/Documents/crowd-counting/src/inference/System/Director/ProjectDirector.py", line 118, in setFlux
    asyncio.run(self.__play(
  File "/opt/anaconda3/lib/python3.9/asyncio/runners.py", line 44, in run
    return loop.run_until_complete(main)
  File "/opt/anaconda3/lib/python3.9/asyncio/base_events.py", line 647, in run_until_complete
    return future.result()
  File "/Users/l03542515/Documents/crowd-counting/src/inference/System/Director/ProjectDirector.py", line 81, in __play
    person_entities = await infer.create_person_entities(camera_entities)
  File "/Users/l03542515/Documents/crowd-counting/src/inference/System/App/InferProcedures/InferProcedures.py", line 57, in create_person_entities
    entities = await self.orion.infer(camera, filevideo)
  File "/Users/l03542515/Documents/crowd-counting/src/inference/System/App/OrionProcedures/OrionProcedures.py", line 101, in infer
    homography = await self.get_homography(camera)
  File "/Users/l03542515/Documents/crowd-counting/src/inference/System/App/OrionProcedures/OrionProcedures.py", line 194, in get_homography
    calibration_data = await self.client.get('urn:ngsi-ld:calibrations:' + camera['id'].split(':')[3])
  File "/opt/anaconda3/lib/python3.9/site-packages/ngsildclient/api/asyn/client.py", line 257, in get
    return await self.entities.get(entity, ctx, asdict, **kwargs)
  File "/opt/anaconda3/lib/python3.9/site-packages/ngsildclient/api/exceptions.py", line 199, in inner_function
    raise exception(pd)

>>>>>>>>>>>>>>[ERROR_DESC]<<<<<<<<<<<<<<<

  [NgsiResourceNotFoundError]:Entity Not Found : urn:ngsi-ld:calibrations:2

>>>>>>>>>>>>>>>>>>>><<<<<<<<<<<<<<<<<<<<<

