---------------------------------
[2023-09-11 13:58:14][INFO][200]:La conexion [dbconn_standard] esta desabilitada en el archivo .config
---------------------------------
[2023-09-11 13:58:14][INFO][200]:Iniciando ...
---------------------------------
[2023-09-11 13:58:14][INFO][200]:Se van a inferir 24 entidades
---------------------------------
[2023-09-11 13:58:15][EXCEPTION][500]:PYTHON-EXCEPTION:

>>>>>>>>>>>>>>>[TRACEBACK]<<<<<<<<<<<<<<<

  File "/home/alanromero/crowd-counting/src/inference/main.py", line 10, in <module>
    ProjectDirector.go( sys.argv )
  File "/home/alanromero/crowd-counting/src/inference/System/Director/ProjectDirector.py", line 141, in go
    ProjectDirector().setFlux( argv )
  File "/home/alanromero/crowd-counting/src/inference/System/Director/ProjectDirector.py", line 121, in setFlux
    asyncio.run(self.__play(
  File "/home/alanromero/anaconda3/lib/python3.10/asyncio/runners.py", line 44, in run
    return loop.run_until_complete(main)
  File "/home/alanromero/anaconda3/lib/python3.10/asyncio/base_events.py", line 649, in run_until_complete
    return future.result()
  File "/home/alanromero/crowd-counting/src/inference/System/Director/ProjectDirector.py", line 82, in __play
    person_entities = await infer.create_person_entities(camera_entities)
  File "/home/alanromero/crowd-counting/src/inference/System/App/InferProcedures/InferProcedures.py", line 59, in create_person_entities
    entities.append( await self.orion.infer(camera, filevideo))
  File "/home/alanromero/crowd-counting/src/inference/System/App/OrionProcedures/OrionProcedures.py", line 101, in infer
    homography = await self.get_homography(camera)
  File "/home/alanromero/crowd-counting/src/inference/System/App/OrionProcedures/OrionProcedures.py", line 197, in get_homography
    calibration_data = await self.client.get('urn:ngsi-ld:calibrations:' + map_front[camera['id'].split(':')[3]])
  File "/home/alanromero/anaconda3/lib/python3.10/site-packages/ngsildclient/api/asyn/client.py", line 257, in get
    return await self.entities.get(entity, ctx, asdict, **kwargs)
  File "/home/alanromero/anaconda3/lib/python3.10/site-packages/ngsildclient/api/exceptions.py", line 199, in inner_function
    raise exception(pd)

>>>>>>>>>>>>>>[ERROR_DESC]<<<<<<<<<<<<<<<

  [NgsiResourceNotFoundError]:Entity Not Found : urn:ngsi-ld:calibrations:0

>>>>>>>>>>>>>>>>>>>><<<<<<<<<<<<<<<<<<<<<

