---------------------------------
[2024-01-04 22:11:05][INFO][200]:La conexion [dbconn_standard] esta desabilitada en el archivo .config
---------------------------------
[2024-01-04 22:11:05][INFO][200]:Iniciando ...
---------------------------------
[2024-01-04 22:11:05][INFO][200]:Se van a inferir 24 entidades
---------------------------------
[2024-01-04 22:11:06][EXCEPTION][500]:PYTHON-EXCEPTION:

>>>>>>>>>>>>>>>[TRACEBACK]<<<<<<<<<<<<<<<

  File "/home/alanromero/crowd-counting/src/inference/main.py", line 10, in <module>
    ProjectDirector.go( sys.argv )
  File "/home/alanromero/crowd-counting/src/inference/System/Director/ProjectDirector.py", line 141, in go
    ProjectDirector().setFlux( argv )
  File "/home/alanromero/crowd-counting/src/inference/System/Director/ProjectDirector.py", line 121, in setFlux
    asyncio.run(self.__play(
  File "/home/alanromero/anaconda3/envs/infer/lib/python3.10/asyncio/runners.py", line 44, in run
    return loop.run_until_complete(main)
  File "/home/alanromero/anaconda3/envs/infer/lib/python3.10/asyncio/base_events.py", line 649, in run_until_complete
    return future.result()
  File "/home/alanromero/crowd-counting/src/inference/System/Director/ProjectDirector.py", line 82, in __play
    person_entities = await infer.create_person_entities(camera_entities)
  File "/home/alanromero/crowd-counting/src/inference/System/App/InferProcedures/InferProcedures.py", line 57, in create_person_entities
    self.scrambler.decryptFile(filevideo)
  File "/home/alanromero/crowd-counting/src/inference/System/App/Scrambling/Scrambling.py", line 76, in decryptFile
    key = cipher.decrypt( infile.read(cls.HASH_SIZE))
  File "/home/alanromero/anaconda3/envs/infer/lib/python3.10/site-packages/Crypto/Cipher/PKCS1_OAEP.py", line 191, in decrypt
    raise ValueError("Incorrect decryption.")

>>>>>>>>>>>>>>[ERROR_DESC]<<<<<<<<<<<<<<<

  [ValueError]:Incorrect decryption.

>>>>>>>>>>>>>>>>>>>><<<<<<<<<<<<<<<<<<<<<

