---------------------------------
[2023-09-08 15:00:33][INFO][200]:La conexion [dbconn_standard] esta desabilitada en el archivo .config
---------------------------------
[2023-09-08 15:00:33][INFO][200]:Iniciando ...
---------------------------------
[2023-09-08 15:00:33][INFO][200]:Se van a inferir 3 entidades
---------------------------------
[2023-09-08 15:00:33][EXCEPTION][500]:PYTHON-EXCEPTION:

>>>>>>>>>>>>>>>[TRACEBACK]<<<<<<<<<<<<<<<

  File "/Users/l03542515/Documents/crowd-counting/src/inference/main.py", line 10, in <module>
    ProjectDirector.go( sys.argv )
  File "/Users/l03542515/Documents/crowd-counting/src/inference/System/Director/ProjectDirector.py", line 138, in go
    ProjectDirector().setFlux( argv )
  File "/Users/l03542515/Documents/crowd-counting/src/inference/System/Director/ProjectDirector.py", line 118, in setFlux
    asyncio.run(self.__play(
  File "/opt/anaconda3/lib/python3.9/asyncio/runners.py", line 44, in run
    return loop.run_until_complete(main)
  File "/opt/anaconda3/lib/python3.9/asyncio/base_events.py", line 647, in run_until_complete
    return future.result()
  File "/Users/l03542515/Documents/crowd-counting/src/inference/System/Director/ProjectDirector.py", line 80, in __play
    infer = InferProcedures()
  File "/Users/l03542515/Documents/crowd-counting/src/inference/System/App/InferProcedures/InferProcedures.py", line 37, in __init__
    self.s3_client = boto3.client('s3',
  File "/opt/anaconda3/lib/python3.9/site-packages/boto3/__init__.py", line 92, in client
    return _get_default_session().client(*args, **kwargs)

>>>>>>>>>>>>>>[ERROR_DESC]<<<<<<<<<<<<<<<

  [TypeError]:client() got an unexpected keyword argument 'access_key_id'

>>>>>>>>>>>>>>>>>>>><<<<<<<<<<<<<<<<<<<<<

