---------------------------------
[2024-01-19 13:28:31][INFO][200]:La conexion [dbconn_standard] esta desabilitada en el archivo .config
---------------------------------
[2024-01-19 13:28:31][INFO][200]:Iniciando ...
---------------------------------
[2024-01-19 13:28:32][INFO][200]:Se van a inferir 9 entidades
---------------------------------
[2024-01-19 13:28:49][EXCEPTION][500]:PYTHON-EXCEPTION:

>>>>>>>>>>>>>>>[TRACEBACK]<<<<<<<<<<<<<<<

  File "/Users/l03542515/Documents/demo_crowd/crowd-counting/src/inference/main.py", line 10, in <module>
    ProjectDirector.go( sys.argv )
  File "/Users/l03542515/Documents/demo_crowd/crowd-counting/src/inference/System/Director/ProjectDirector.py", line 143, in go
    ProjectDirector().setFlux( argv )
  File "/Users/l03542515/Documents/demo_crowd/crowd-counting/src/inference/System/Director/ProjectDirector.py", line 123, in setFlux
    asyncio.run(self.__play(
  File "/opt/anaconda3/lib/python3.9/asyncio/runners.py", line 44, in run
    return loop.run_until_complete(main)
  File "/opt/anaconda3/lib/python3.9/asyncio/base_events.py", line 647, in run_until_complete
    return future.result()
  File "/Users/l03542515/Documents/demo_crowd/crowd-counting/src/inference/System/Director/ProjectDirector.py", line 84, in __play
    person_entities = await infer.create_person_entities(camera_entities)
  File "/Users/l03542515/Documents/demo_crowd/crowd-counting/src/inference/System/App/InferProcedures/InferProcedures.py", line 79, in create_person_entities
    entities.append( self.infer(camera, decryptedF))
  File "/Users/l03542515/Documents/demo_crowd/crowd-counting/src/inference/System/App/InferProcedures/InferProcedures.py", line 154, in infer
    entities = self.track_video(filevideo, model, time)
  File "/Users/l03542515/Documents/demo_crowd/crowd-counting/src/inference/System/App/InferProcedures/InferProcedures.py", line 107, in track_video
    results = model.track(source=frame, persist=True, classes=0)
  File "/opt/anaconda3/lib/python3.9/site-packages/ultralytics/yolo/engine/model.py", line 270, in track
    from ultralytics.tracker import register_tracker
  File "/opt/anaconda3/lib/python3.9/site-packages/ultralytics/tracker/__init__.py", line 3, in <module>
    from .track import register_tracker
  File "/opt/anaconda3/lib/python3.9/site-packages/ultralytics/tracker/track.py", line 10, in <module>
    from .trackers import BOTSORT, BYTETracker
  File "/opt/anaconda3/lib/python3.9/site-packages/ultralytics/tracker/trackers/__init__.py", line 3, in <module>
    from .bot_sort import BOTSORT
  File "/opt/anaconda3/lib/python3.9/site-packages/ultralytics/tracker/trackers/bot_sort.py", line 7, in <module>
    from ..utils import matching
  File "/opt/anaconda3/lib/python3.9/site-packages/ultralytics/tracker/utils/matching.py", line 17, in <module>
    import lap

>>>>>>>>>>>>>>[ERROR_DESC]<<<<<<<<<<<<<<<

  [ModuleNotFoundError]:No module named 'lap'

>>>>>>>>>>>>>>>>>>>><<<<<<<<<<<<<<<<<<<<<

